Workbook

Sheet aggregates
B1: Production by year | E1: Production by entity | F1: tonnes | G1: Production by continent | H1: tonnes | J1: Entity (sorted) | K1: tonnes | L1: Continent (sorted) | M1: tonnes | Y1: Production in 1976 - dimension
E2: {=XLOOKUP(dimension!B2:B83, dimension!B2:B83, dimension!B2:B83)} -> Angola | F2: {=SUMIF(cleaned!B2:B7522, dimension!A2:A83, cleaned!D2:D7522)} -> 3661881.5 | G2: {=XLOOKUP(extra!B2:B6,extra!B2:B6,extra!B2:B6)} -> Africa | H2: {=SUMIF(cleaned!A2:A7522,G2:G6,cleaned!D2:D7522)} -> 79298583 | J2: {=SORT(HSTACK(E2:E7522,F2:F7522),2,FALSE)} -> Brazil | K2: 123792215 | L2: {=SORT(HSTACK(G2:G7522,H2:H7522),2,FALSE)} -> South America | M2: 1.8607325e+08 | Q2: Production for each entity in 1976 | T2: =IFERROR(__xludf.DUMMYFUNCTION("QUERY(cleaned!A2:D7522, ""select C, sum(D) where B = 'BRA' group by C,D label C 'Year', sum(D) 'Brazil'"", 1)"),"Year") -> Year | U2: =IFERROR(__xludf.DUMMYFUNCTION("""COMPUTED_VALUE"""),"Brazil") -> Brazil | V2: =IFERROR(__xludf.DUMMYFUNCTION("QUERY(cleaned!A2:D7522, ""select sum(D) where B = 'BRA' group by D label sum(D) 'South America'"", 1)"),"South America") -> South America | Y2: {=XLOOKUP(dimension!B2:B83, dimension!B2:B83, dimension!B2:B83)} -> Angola | Z2: {=SUMIFS(cleaned!D2:D7522, cleaned!B2:B7522, dimension!A2:A83, cleaned!C2:C7522, 1976)} -> 57480
B3: =IFERROR(__xludf.DUMMYFUNCTION("QUERY(cleaned!C2:D7522, ""select C, sum(D) group by C"")"),"") | C3: =IFERROR(__xludf.DUMMYFUNCTION("""COMPUTED_VALUE"""),"sum ") -> sum | E3: Belize | F3: 2974.91 | G3: Asia | H3: 91799352 | J3: Colombia | K3: 42111833 | L3: Asia | M3: 91799352 | O3: Year of least production | P3: {=XLOOKUP(MIN(categories!C261:C324),categories!C261:C324,categories!B261:B324)} -> 1976 | Q3: =IFERROR(__xludf.DUMMYFUNCTION("SORT(QUERY(cleaned!A2:D7522,""select A, sum(D) where C = 1976 group by A, C""),2, FALSE)"),"") | R3: =IFERROR(__xludf.DUMMYFUNCTION("""COMPUTED_VALUE"""),"sum ") -> sum | T3: =IFERROR(__xludf.DUMMYFUNCTION("""COMPUTED_VALUE"""),1961.0) -> 1961 | U3: =IFERROR(__xludf.DUMMYFUNCTION("""COMPUTED_VALUE"""),2228704.0) -> 2228704 | V3: =IFERROR(__xludf.DUMMYFUNCTION("""COMPUTED_VALUE"""),375985.0) -> 375985 | Y3: Belize | Z3: {=SUMIFS(cleaned!D3:D7522, cleaned!B3:B7522, dimension!A3:A84, cleaned!C3:C7522, 1976)} -> 0
E4: Benin | F4: 39267.64 | G4: North America | H4: 64746897 | J4: Vietnam | K4: 35743437 | L4: Africa | M4: 79298583 | Q4: =IFERROR(__xludf.DUMMYFUNCTION("""COMPUTED_VALUE"""),"Africa") -> Africa | R4: =IFERROR(__xludf.DUMMYFUNCTION("""COMPUTED_VALUE"""),1165512.0) -> 1165512 | T4: =IFERROR(__xludf.DUMMYFUNCTION("""COMPUTED_VALUE"""),1962.0) -> 1962 | U4: =IFERROR(__xludf.DUMMYFUNCTION("""COMPUTED_VALUE"""),2190303.0) -> 2190303 | V4: =IFERROR(__xludf.DUMMYFUNCTION("""COMPUTED_VALUE"""),754800.0) -> 754800 | Y4: Benin | Z4: {=SUMIFS(cleaned!D4:D7522, cleaned!B4:B7522, dimension!A4:A85, cleaned!C4:C7522, 1976)} -> 599
B5: =IFERROR(__xludf.DUMMYFUNCTION("""COMPUTED_VALUE"""),1961.0) -> 1961 | C5: =IFERROR(__xludf.DUMMYFUNCTION("""COMPUTED_VALUE"""),9060993.0) -> 9060993 | E5: Bolivia | F5: 1246437.3 | G5: Europe | H5: 207 | J5: Indonesia | K5: 28224094 | L5: North America | M5: 64746897 | Q5: =IFERROR(__xludf.DUMMYFUNCTION("""COMPUTED_VALUE"""),"South America") -> South America | R5: =IFERROR(__xludf.DUMMYFUNCTION("""COMPUTED_VALUE"""),1071431.0) -> 1071431 | T5: =IFERROR(__xludf.DUMMYFUNCTION("""COMPUTED_VALUE"""),1963.0) -> 1963 | U5: =IFERROR(__xludf.DUMMYFUNCTION("""COMPUTED_VALUE"""),1650527.0) -> 1650527 | V5: =IFERROR(__xludf.DUMMYFUNCTION("""COMPUTED_VALUE"""),872897.0) -> 872897 | Y5: Bolivia | Z5: {=SUMIFS(cleaned!D5:D7522, cleaned!B5:B7522, dimension!A5:A86, cleaned!C5:C7522, 1976)} -> 14664
B6: =IFERROR(__xludf.DUMMYFUNCTION("""COMPUTED_VALUE"""),1962.0) -> 1962 | C6: =IFERROR(__xludf.DUMMYFUNCTION("""COMPUTED_VALUE"""),9175614.0) -> 9175614 | E6: Brazil | F6: 123792215 | G6: South America | H6: 1.8607325e+08 | J6: Ethiopia | K6: 16774867 | L6: Europe | M6: 207 | Q6: =IFERROR(__xludf.DUMMYFUNCTION("""COMPUTED_VALUE"""),"North America") -> North America | R6: =IFERROR(__xludf.DUMMYFUNCTION("""COMPUTED_VALUE"""),834112.0) -> 834112 | T6: =IFERROR(__xludf.DUMMYFUNCTION("""COMPUTED_VALUE"""),1964.0) -> 1964 | U6: =IFERROR(__xludf.DUMMYFUNCTION("""COMPUTED_VALUE"""),1042013.0) -> 1042013 | V6: =IFERROR(__xludf.DUMMYFUNCTION("""COMPUTED_VALUE"""),930135.0) -> 930135 | Y6: Brazil | Z6: {=SUMIFS(cleaned!D6:D7522, cleaned!B6:B7522, dimension!A6:A87, cleaned!C6:C7522, 1976)} -> 375985
B7: =IFERROR(__xludf.DUMMYFUNCTION("""COMPUTED_VALUE"""),1963.0) -> 1963 | C7: =IFERROR(__xludf.DUMMYFUNCTION("""COMPUTED_VALUE"""),8312263.0) -> 8312263 | E7: Burundi | F7: 2162310.5 | J7: Mexico | K7: 15944907 | Q7: =IFERROR(__xludf.DUMMYFUNCTION("""COMPUTED_VALUE"""),"Colombia") -> Colombia | R7: =IFERROR(__xludf.DUMMYFUNCTION("""COMPUTED_VALUE"""),483000.0) -> 483000 | T7: =IFERROR(__xludf.DUMMYFUNCTION("""COMPUTED_VALUE"""),1965.0) -> 1965 | U7: =IFERROR(__xludf.DUMMYFUNCTION("""COMPUTED_VALUE"""),2294047.0) -> 2294047 | V7: =IFERROR(__xludf.DUMMYFUNCTION("""COMPUTED_VALUE"""),957931.0) -> 957931 | Y7: Burundi | Z7: {=SUMIFS(cleaned!D7:D7522, cleaned!B7:B7522, dimension!A7:A88, cleaned!C7:C7522, 1976)} -> 21428
B8: =IFERROR(__xludf.DUMMYFUNCTION("""COMPUTED_VALUE"""),1964.0) -> 1964 | C8: =IFERROR(__xludf.DUMMYFUNCTION("""COMPUTED_VALUE"""),7549247.0) -> 7549247 | E8: Cambodia | F8: 17504.14 | J8: Guatemala | K8: 12791943 | Q8: =IFERROR(__xludf.DUMMYFUNCTION("""COMPUTED_VALUE"""),"Asia") -> Asia | R8: =IFERROR(__xludf.DUMMYFUNCTION("""COMPUTED_VALUE"""),410280.0) -> 410280 | T8: =IFERROR(__xludf.DUMMYFUNCTION("""COMPUTED_VALUE"""),1966.0) -> 1966 | U8: =IFERROR(__xludf.DUMMYFUNCTION("""COMPUTED_VALUE"""),1202868.0) -> 1202868 | V8: =IFERROR(__xludf.DUMMYFUNCTION("""COMPUTED_VALUE"""),975385.0) -> 975385 | Y8: Cambodia | Z8: {=SUMIFS(cleaned!D8:D7522, cleaned!B8:B7522, dimension!A8:A89, cleaned!C8:C7522, 1976)} -> 90
B9: =IFERROR(__xludf.DUMMYFUNCTION("""COMPUTED_VALUE"""),1965.0) -> 1965 | C9: =IFERROR(__xludf.DUMMYFUNCTION("""COMPUTED_VALUE"""),9975063.0) -> 9975063 | E9: Cameroon | F9: 4667182.4 | J9: Uganda | K9: 12696994 | Q9: =IFERROR(__xludf.DUMMYFUNCTION("""COMPUTED_VALUE"""),"Brazil") -> Brazil | R9: =IFERROR(__xludf.DUMMYFUNCTION("""COMPUTED_VALUE"""),375985.0) -> 375985 | T9: =IFERROR(__xludf.DUMMYFUNCTION("""COMPUTED_VALUE"""),1967.0) -> 1967 | U9: =IFERROR(__xludf.DUMMYFUNCTION("""COMPUTED_VALUE"""),1507500.0) -> 1507500 | V9: =IFERROR(__xludf.DUMMYFUNCTION("""COMPUTED_VALUE"""),1041406.0) -> 1041406 | Y9: Cameroon | Z9: {=SUMIFS(cleaned!D9:D7522, cleaned!B9:B7522, dimension!A9:A90, cleaned!C9:C7522, 1976)} -> 79599
B10: =IFERROR(__xludf.DUMMYFUNCTION("""COMPUTED_VALUE"""),1966.0) -> 1966 | C10: =IFERROR(__xludf.DUMMYFUNCTION("""COMPUTED_VALUE"""),8118518.0) -> 8118518 | E10: Cape Verde | F10: 2931.22 | J10: India | K10: 12584852 | Q10: =IFERROR(__xludf.DUMMYFUNCTION("""COMPUTED_VALUE"""),"Cote d'Ivoire") -> Cote d'Ivoire | R10: =IFERROR(__xludf.DUMMYFUNCTION("""COMPUTED_VALUE"""),308400.0) -> 308400 | T10: =IFERROR(__xludf.DUMMYFUNCTION("""COMPUTED_VALUE"""),1968.0) -> 1968 | U10: =IFERROR(__xludf.DUMMYFUNCTION("""COMPUTED_VALUE"""),1057700.0) -> 1057700 | V10: =IFERROR(__xludf.DUMMYFUNCTION("""COMPUTED_VALUE"""),1042013.0) -> 1042013 | Y10: Cape Verde | Z10: {=SUMIFS(cleaned!D10:D7522, cleaned!B10:B7522, dimension!A10:A91, cleaned!C10:C7522, 1976)} -> 168
B11: =IFERROR(__xludf.DUMMYFUNCTION("""COMPUTED_VALUE"""),1967.0) -> 1967 | C11: =IFERROR(__xludf.DUMMYFUNCTION("""COMPUTED_VALUE"""),8683212.0) -> 8683212 | E11: Central African Republic | F11: 2477345.5 | J11: Cote d'Ivoire | K11: 12557421 | Q11: =IFERROR(__xludf.DUMMYFUNCTION("""COMPUTED_VALUE"""),"Mexico") -> Mexico | R11: =IFERROR(__xludf.DUMMYFUNCTION("""COMPUTED_VALUE"""),212200.0) -> 212200 | T11: =IFERROR(__xludf.DUMMYFUNCTION("""COMPUTED_VALUE"""),1969.0) -> 1969 | U11: =IFERROR(__xludf.DUMMYFUNCTION("""COMPUTED_VALUE"""),1283500.0) -> 1283500 | V11: =IFERROR(__xludf.DUMMYFUNCTION("""COMPUTED_VALUE"""),1057700.0) -> 1057700 | Y11: Central African Republic | Z11: {=SUMIFS(cleaned!D11:D7522, cleaned!B11:B7522, dimension!A11:A92, cleaned!C11:C7522, 1976)} -> 13900
B12: =IFERROR(__xludf.DUMMYFUNCTION("""COMPUTED_VALUE"""),1968.0) -> 1968 | C12: =IFERROR(__xludf.DUMMYFUNCTION("""COMPUTED_VALUE"""),7888930.0) -> 7888930 | E12: China | F12: 2040412.3 | J12: Honduras | K12: 10332337 | Q12: =IFERROR(__xludf.DUMMYFUNCTION("""COMPUTED_VALUE"""),"Indonesia") -> Indonesia | R12: =IFERROR(__xludf.DUMMYFUNCTION("""COMPUTED_VALUE"""),193377.0) -> 193377 | T12: =IFERROR(__xludf.DUMMYFUNCTION("""COMPUTED_VALUE"""),1970.0) -> 1970 | U12: =IFERROR(__xludf.DUMMYFUNCTION("""COMPUTED_VALUE"""),754800.0) -> 754800 | V12: =IFERROR(__xludf.DUMMYFUNCTION("""COMPUTED_VALUE"""),1061195.0) -> 1061195 | Y12: China | Z12: {=SUMIFS(cleaned!D12:D7522, cleaned!B12:B7522, dimension!A12:A93, cleaned!C12:C7522, 1976)} -> 4000
B13: =IFERROR(__xludf.DUMMYFUNCTION("""COMPUTED_VALUE"""),1969.0) -> 1969 | C13: =IFERROR(__xludf.DUMMYFUNCTION("""COMPUTED_VALUE"""),8568392.0) -> 8568392 | E13: Colombia | F13: 42111833 | J13: Peru | K13: 10243687 | Q13: =IFERROR(__xludf.DUMMYFUNCTION("""COMPUTED_VALUE"""),"Ethiopia") -> Ethiopia | R13: =IFERROR(__xludf.DUMMYFUNCTION("""COMPUTED_VALUE"""),178600.0) -> 178600 | T13: =IFERROR(__xludf.DUMMYFUNCTION("""COMPUTED_VALUE"""),1971.0) -> 1971 | U13: =IFERROR(__xludf.DUMMYFUNCTION("""COMPUTED_VALUE"""),1551462.0) -> 1551462 | V13: =IFERROR(__xludf.DUMMYFUNCTION("""COMPUTED_VALUE"""),1202868.0) -> 1202868 | Y13: Colombia | Z13: {=SUMIFS(cleaned!D13:D7522, cleaned!B13:B7522, dimension!A13:A94, cleaned!C13:C7522, 1976)} -> 483000
B14: =IFERROR(__xludf.DUMMYFUNCTION("""COMPUTED_VALUE"""),1970.0) -> 1970 | C14: =IFERROR(__xludf.DUMMYFUNCTION("""COMPUTED_VALUE"""),7727944.0) -> 7727944 | E14: Comoros | F14: 7237.55 | J14: El Salvador | K14: 7246445.3 | Q14: =IFERROR(__xludf.DUMMYFUNCTION("""COMPUTED_VALUE"""),"Guatemala") -> Guatemala | R14: =IFERROR(__xludf.DUMMYFUNCTION("""COMPUTED_VALUE"""),158433.0) -> 158433 | T14: =IFERROR(__xludf.DUMMYFUNCTION("""COMPUTED_VALUE"""),1972.0) -> 1972 | U14: =IFERROR(__xludf.DUMMYFUNCTION("""COMPUTED_VALUE"""),1495705.0) -> 1495705 | V14: =IFERROR(__xludf.DUMMYFUNCTION("""COMPUTED_VALUE"""),1228513.0) -> 1228513 | Y14: Comoros | Z14: {=SUMIFS(cleaned!D14:D7522, cleaned!B14:B7522, dimension!A14:A95, cleaned!C14:C7522, 1976)} -> 60
B15: =IFERROR(__xludf.DUMMYFUNCTION("""COMPUTED_VALUE"""),1971.0) -> 1971 | C15: =IFERROR(__xludf.DUMMYFUNCTION("""COMPUTED_VALUE"""),9354920.0) -> 9354920 | E15: Congo | F15: 142309.92 | J15: Costa Rica | K15: 6826334.6 | Q15: =IFERROR(__xludf.DUMMYFUNCTION("""COMPUTED_VALUE"""),"El Salvador") -> El Salvador | R15: =IFERROR(__xludf.DUMMYFUNCTION("""COMPUTED_VALUE"""),138690.0) -> 138690 | T15: =IFERROR(__xludf.DUMMYFUNCTION("""COMPUTED_VALUE"""),1973.0) -> 1973 | U15: =IFERROR(__xludf.DUMMYFUNCTION("""COMPUTED_VALUE"""),872897.0) -> 872897 | V15: =IFERROR(__xludf.DUMMYFUNCTION("""COMPUTED_VALUE"""),1267661.0) -> 1267661 | Y15: Congo | Z15: {=SUMIFS(cleaned!D15:D7522, cleaned!B15:B7522, dimension!A15:A96, cleaned!C15:C7522, 1976)} -> 2160
B16: =IFERROR(__xludf.DUMMYFUNCTION("""COMPUTED_VALUE"""),1972.0) -> 1972 | C16: =IFERROR(__xludf.DUMMYFUNCTION("""COMPUTED_VALUE"""),9171824.0) -> 9171824 | E16: Cook Islands | F16: 280.38 | J16: Philippines | K16: 5852956 | Q16: =IFERROR(__xludf.DUMMYFUNCTION("""COMPUTED_VALUE"""),"Uganda") -> Uganda | R16: =IFERROR(__xludf.DUMMYFUNCTION("""COMPUTED_VALUE"""),137100.0) -> 137100 | T16: =IFERROR(__xludf.DUMMYFUNCTION("""COMPUTED_VALUE"""),1974.0) -> 1974 | U16: =IFERROR(__xludf.DUMMYFUNCTION("""COMPUTED_VALUE"""),1615309.0) -> 1615309 | V16: =IFERROR(__xludf.DUMMYFUNCTION("""COMPUTED_VALUE"""),1272298.0) -> 1272298 | Y16: Cook Islands | Z16: {=SUMIFS(cleaned!D16:D7522, cleaned!B16:B7522, dimension!A16:A97, cleaned!C16:C7522, 1976)} -> 2
B17: =IFERROR(__xludf.DUMMYFUNCTION("""COMPUTED_VALUE"""),1973.0) -> 1973 | C17: =IFERROR(__xludf.DUMMYFUNCTION("""COMPUTED_VALUE"""),8408049.0) -> 8408049 | E17: Costa Rica | F17: 6826334.6 | J17: Cameroon | K17: 4667182.4 | Q17: =IFERROR(__xludf.DUMMYFUNCTION("""COMPUTED_VALUE"""),"Democratic Republic of Congo") -> Democratic Republic of Congo | R17: =IFERROR(__xludf.DUMMYFUNCTION("""COMPUTED_VALUE"""),91100.0) -> 91100 | T17: =IFERROR(__xludf.DUMMYFUNCTION("""COMPUTED_VALUE"""),1975.0) -> 1975 | U17: =IFERROR(__xludf.DUMMYFUNCTION("""COMPUTED_VALUE"""),1272298.0) -> 1272298 | V17: =IFERROR(__xludf.DUMMYFUNCTION("""COMPUTED_VALUE"""),1278759.0) -> 1278759 | Y17: Costa Rica | Z17: {=SUMIFS(cleaned!D17:D7522, cleaned!B17:B7522, dimension!A17:A98, cleaned!C17:C7522, 1976)} -> 81784
B18: =IFERROR(__xludf.DUMMYFUNCTION("""COMPUTED_VALUE"""),1974.0) -> 1974 | C18: =IFERROR(__xludf.DUMMYFUNCTION("""COMPUTED_VALUE"""),9575410.0) -> 9575410 | E18: Cote d'Ivoire | F18: 12557421 | J18: Madagascar | K18: 4295567.6 | Q18: =IFERROR(__xludf.DUMMYFUNCTION("""COMPUTED_VALUE"""),"Ecuador") -> Ecuador | R18: =IFERROR(__xludf.DUMMYFUNCTION("""COMPUTED_VALUE"""),87101.0) -> 87101 | T18: =IFERROR(__xludf.DUMMYFUNCTION("""COMPUTED_VALUE"""),1976.0) -> 1976 | U18: =IFERROR(__xludf.DUMMYFUNCTION("""COMPUTED_VALUE"""),375985.0) -> 375985 | V18: =IFERROR(__xludf.DUMMYFUNCTION("""COMPUTED_VALUE"""),1283500.0) -> 1283500 | Y18: Cote d'Ivoire | Z18: {=SUMIFS(cleaned!D18:D7522, cleaned!B18:B7522, dimension!A18:A99, cleaned!C18:C7522, 1976)} -> 308400
B19: =IFERROR(__xludf.DUMMYFUNCTION("""COMPUTED_VALUE"""),1975.0) -> 1975 | C19: =IFERROR(__xludf.DUMMYFUNCTION("""COMPUTED_VALUE"""),9245128.0) -> 9245128 | E19: Cuba | F19: 1202993.3 | J19: Nicaragua | K19: 4279110.3 | Q19: =IFERROR(__xludf.DUMMYFUNCTION("""COMPUTED_VALUE"""),"India") -> India | R19: =IFERROR(__xludf.DUMMYFUNCTION("""COMPUTED_VALUE"""),84000.0) -> 84000 | T19: =IFERROR(__xludf.DUMMYFUNCTION("""COMPUTED_VALUE"""),1977.0) -> 1977 | U19: =IFERROR(__xludf.DUMMYFUNCTION("""COMPUTED_VALUE"""),975385.0) -> 975385 | V19: =IFERROR(__xludf.DUMMYFUNCTION("""COMPUTED_VALUE"""),1294373.0) -> 1294373 | Y19: Cuba | Z19: {=SUMIFS(cleaned!D19:D7522, cleaned!B19:B7522, dimension!A19:A100, cleaned!C19:C7522, 1976)} -> 27151
B20: =IFERROR(__xludf.DUMMYFUNCTION("""COMPUTED_VALUE"""),1976.0) -> 1976 | C20: =IFERROR(__xludf.DUMMYFUNCTION("""COMPUTED_VALUE"""),7086181.0) -> 7086181 | E20: Democratic Republic of Congo | F20: 4084986.2 | J20: Ecuador | K20: 4255663.9 | Q20: =IFERROR(__xludf.DUMMYFUNCTION("""COMPUTED_VALUE"""),"Costa Rica") -> Costa Rica | R20: =IFERROR(__xludf.DUMMYFUNCTION("""COMPUTED_VALUE"""),81784.0) -> 81784 | T20: =IFERROR(__xludf.DUMMYFUNCTION("""COMPUTED_VALUE"""),1978.0) -> 1978 | U20: =IFERROR(__xludf.DUMMYFUNCTION("""COMPUTED_VALUE"""),1267661.0) -> 1267661 | V20: =IFERROR(__xludf.DUMMYFUNCTION("""COMPUTED_VALUE"""),1307289.0) -> 1307289 | Y20: Democratic Republic of Congo | Z20: {=SUMIFS(cleaned!D20:D7522, cleaned!B20:B7522, dimension!A20:A101, cleaned!C20:C7522, 1976)} -> 91100
B21: =IFERROR(__xludf.DUMMYFUNCTION("""COMPUTED_VALUE"""),1977.0) -> 1977 | C21: =IFERROR(__xludf.DUMMYFUNCTION("""COMPUTED_VALUE"""),8837726.0) -> 8837726 | E21: Dominica | F21: 12363.02 | J21: Kenya | K21: 4181454 | Q21: =IFERROR(__xludf.DUMMYFUNCTION("""COMPUTED_VALUE"""),"Philippines") -> Philippines | R21: =IFERROR(__xludf.DUMMYFUNCTION("""COMPUTED_VALUE"""),80800.0) -> 80800 | T21: =IFERROR(__xludf.DUMMYFUNCTION("""COMPUTED_VALUE"""),1979.0) -> 1979 | U21: =IFERROR(__xludf.DUMMYFUNCTION("""COMPUTED_VALUE"""),1332772.0) -> 1332772 | V21: =IFERROR(__xludf.DUMMYFUNCTION("""COMPUTED_VALUE"""),1332772.0) -> 1332772 | Y21: Dominica | Z21: {=SUMIFS(cleaned!D21:D7522, cleaned!B21:B7522, dimension!A21:A102, cleaned!C21:C7522, 1976)} -> 0
B22: =IFERROR(__xludf.DUMMYFUNCTION("""COMPUTED_VALUE"""),1978.0) -> 1978 | C22: =IFERROR(__xludf.DUMMYFUNCTION("""COMPUTED_VALUE"""),9497051.0) -> 9497051 | E22: Dominican Republic | F22: 2679181.2 | J22: Democratic Republic of Congo | K22: 4084986.2 | Q22: =IFERROR(__xludf.DUMMYFUNCTION("""COMPUTED_VALUE"""),"Kenya") -> Kenya | R22: =IFERROR(__xludf.DUMMYFUNCTION("""COMPUTED_VALUE"""),80303.0) -> 80303 | T22: =IFERROR(__xludf.DUMMYFUNCTION("""COMPUTED_VALUE"""),1980.0) -> 1980 | U22: =IFERROR(__xludf.DUMMYFUNCTION("""COMPUTED_VALUE"""),1061195.0) -> 1061195 | V22: =IFERROR(__xludf.DUMMYFUNCTION("""COMPUTED_VALUE"""),1348014.0) -> 1348014 | Y22: Dominican Republic | Z22: {=SUMIFS(cleaned!D22:D7522, cleaned!B22:B7522, dimension!A22:A103, cleaned!C22:C7522, 1976)} -> 56997
B23: =IFERROR(__xludf.DUMMYFUNCTION("""COMPUTED_VALUE"""),1979.0) -> 1979 | C23: =IFERROR(__xludf.DUMMYFUNCTION("""COMPUTED_VALUE"""),9996678.0) -> 9996678 | E23: East Timor | F23: 512423.74 | J23: Venezuela | K23: 4004490.9 | Q23: =IFERROR(__xludf.DUMMYFUNCTION("""COMPUTED_VALUE"""),"Cameroon") -> Cameroon | R23: =IFERROR(__xludf.DUMMYFUNCTION("""COMPUTED_VALUE"""),79599.0) -> 79599 | T23: =IFERROR(__xludf.DUMMYFUNCTION("""COMPUTED_VALUE"""),1981.0) -> 1981 | U23: =IFERROR(__xludf.DUMMYFUNCTION("""COMPUTED_VALUE"""),2032210.0) -> 2032210 | V23: =IFERROR(__xludf.DUMMYFUNCTION("""COMPUTED_VALUE"""),1369196.0) -> 1369196 | Y23: East Timor | Z23: {=SUMIFS(cleaned!D23:D7522, cleaned!B23:B7522, dimension!A23:A104, cleaned!C23:C7522, 1976)} -> 6000
B24: =IFERROR(__xludf.DUMMYFUNCTION("""COMPUTED_VALUE"""),1980.0) -> 1980 | C24: =IFERROR(__xludf.DUMMYFUNCTION("""COMPUTED_VALUE"""),9734129.0) -> 9734129 | E24: Ecuador | F24: 4255663.9 | J24: Angola | K24: 3661881.5 | Q24: =IFERROR(__xludf.DUMMYFUNCTION("""COMPUTED_VALUE"""),"Madagascar") -> Madagascar | R24: =IFERROR(__xludf.DUMMYFUNCTION("""COMPUTED_VALUE"""),78930.0) -> 78930 | T24: =IFERROR(__xludf.DUMMYFUNCTION("""COMPUTED_VALUE"""),1982.0) -> 1982 | U24: =IFERROR(__xludf.DUMMYFUNCTION("""COMPUTED_VALUE"""),957931.0) -> 957931 | V24: =IFERROR(__xludf.DUMMYFUNCTION("""COMPUTED_VALUE"""),1420281.0) -> 1420281 | Y24: Ecuador | Z24: {=SUMIFS(cleaned!D24:D7522, cleaned!B24:B7522, dimension!A24:A105, cleaned!C24:C7522, 1976)} -> 87101
B25: =IFERROR(__xludf.DUMMYFUNCTION("""COMPUTED_VALUE"""),1981.0) -> 1981 | C25: =IFERROR(__xludf.DUMMYFUNCTION("""COMPUTED_VALUE"""),1.2217094E7) -> 12217094 | E25: El Salvador | F25: 7246445.3 | J25: Tanzania | K25: 3419867 | Q25: =IFERROR(__xludf.DUMMYFUNCTION("""COMPUTED_VALUE"""),"Peru") -> Peru | R25: =IFERROR(__xludf.DUMMYFUNCTION("""COMPUTED_VALUE"""),65445.0) -> 65445 | T25: =IFERROR(__xludf.DUMMYFUNCTION("""COMPUTED_VALUE"""),1983.0) -> 1983 | U25: =IFERROR(__xludf.DUMMYFUNCTION("""COMPUTED_VALUE"""),1671588.0) -> 1671588 | V25: =IFERROR(__xludf.DUMMYFUNCTION("""COMPUTED_VALUE"""),1464856.0) -> 1464856 | Y25: El Salvador | Z25: {=SUMIFS(cleaned!D25:D7522, cleaned!B25:B7522, dimension!A25:A106, cleaned!C25:C7522, 1976)} -> 138690
B26: =IFERROR(__xludf.DUMMYFUNCTION("""COMPUTED_VALUE"""),1982.0) -> 1982 | C26: =IFERROR(__xludf.DUMMYFUNCTION("""COMPUTED_VALUE"""),9923338.0) -> 9923338 | E26: Equatorial Guinea | F26: 354356.87 | J26: Guinea | K26: 3280563.7 | Q26: =IFERROR(__xludf.DUMMYFUNCTION("""COMPUTED_VALUE"""),"Angola") -> Angola | R26: =IFERROR(__xludf.DUMMYFUNCTION("""COMPUTED_VALUE"""),57480.0) -> 57480 | T26: =IFERROR(__xludf.DUMMYFUNCTION("""COMPUTED_VALUE"""),1984.0) -> 1984 | U26: =IFERROR(__xludf.DUMMYFUNCTION("""COMPUTED_VALUE"""),1420281.0) -> 1420281 | V26: =IFERROR(__xludf.DUMMYFUNCTION("""COMPUTED_VALUE"""),1495705.0) -> 1495705 | Y26: Equatorial Guinea | Z26: {=SUMIFS(cleaned!D26:D7522, cleaned!B26:B7522, dimension!A26:A107, cleaned!C26:C7522, 1976)} -> 5400
B27: =IFERROR(__xludf.DUMMYFUNCTION("""COMPUTED_VALUE"""),1983.0) -> 1983 | C27: =IFERROR(__xludf.DUMMYFUNCTION("""COMPUTED_VALUE"""),1.1220683E7) -> 11220683 | E27: Ethiopia | F27: 16774867 | J27: Papua New Guinea | K27: 3060184.9 | Q27: =IFERROR(__xludf.DUMMYFUNCTION("""COMPUTED_VALUE"""),"Dominican Republic") -> Dominican Republic | R27: =IFERROR(__xludf.DUMMYFUNCTION("""COMPUTED_VALUE"""),56997.0) -> 56997 | T27: =IFERROR(__xludf.DUMMYFUNCTION("""COMPUTED_VALUE"""),1985.0) -> 1985 | U27: =IFERROR(__xludf.DUMMYFUNCTION("""COMPUTED_VALUE"""),1910646.0) -> 1910646 | V27: =IFERROR(__xludf.DUMMYFUNCTION("""COMPUTED_VALUE"""),1507500.0) -> 1507500 | Y27: Ethiopia | Z27: {=SUMIFS(cleaned!D27:D7522, cleaned!B27:B7522, dimension!A27:A108, cleaned!C27:C7522, 1976)} -> 178600
B28: =IFERROR(__xludf.DUMMYFUNCTION("""COMPUTED_VALUE"""),1984.0) -> 1984 | C28: =IFERROR(__xludf.DUMMYFUNCTION("""COMPUTED_VALUE"""),1.0487169E7) -> 10487169 | E28: Fiji | F28: 2452.04 | J28: Dominican Republic | K28: 2679181.2 | Q28: =IFERROR(__xludf.DUMMYFUNCTION("""COMPUTED_VALUE"""),"Nicaragua") -> Nicaragua | R28: =IFERROR(__xludf.DUMMYFUNCTION("""COMPUTED_VALUE"""),56580.0) -> 56580 | T28: =IFERROR(__xludf.DUMMYFUNCTION("""COMPUTED_VALUE"""),1986.0) -> 1986 | U28: =IFERROR(__xludf.DUMMYFUNCTION("""COMPUTED_VALUE"""),1041406.0) -> 1041406 | V28: =IFERROR(__xludf.DUMMYFUNCTION("""COMPUTED_VALUE"""),1520382.0) -> 1520382 | Y28: Fiji | Z28: {=SUMIFS(cleaned!D28:D7522, cleaned!B28:B7522, dimension!A28:A109, cleaned!C28:C7522, 1976)} -> 15
B29: =IFERROR(__xludf.DUMMYFUNCTION("""COMPUTED_VALUE"""),1985.0) -> 1985 | C29: =IFERROR(__xludf.DUMMYFUNCTION("""COMPUTED_VALUE"""),1.1706014E7) -> 11706014 | E29: Gabon | F29: 35257.58 | J29: Laos | K29: 2500550 | Q29: =IFERROR(__xludf.DUMMYFUNCTION("""COMPUTED_VALUE"""),"Honduras") -> Honduras | R29: =IFERROR(__xludf.DUMMYFUNCTION("""COMPUTED_VALUE"""),48285.0) -> 48285 | T29: =IFERROR(__xludf.DUMMYFUNCTION("""COMPUTED_VALUE"""),1987.0) -> 1987 | U29: =IFERROR(__xludf.DUMMYFUNCTION("""COMPUTED_VALUE"""),2202708.0) -> 2202708 | V29: =IFERROR(__xludf.DUMMYFUNCTION("""COMPUTED_VALUE"""),1532335.0) -> 1532335 | Y29: Gabon | Z29: {=SUMIFS(cleaned!D29:D7522, cleaned!B29:B7522, dimension!A29:A110, cleaned!C29:C7522, 1976)} -> 145
B30: =IFERROR(__xludf.DUMMYFUNCTION("""COMPUTED_VALUE"""),1986.0) -> 1986 | C30: =IFERROR(__xludf.DUMMYFUNCTION("""COMPUTED_VALUE"""),1.0519382E7) -> 10519382 | E30: Ghana | F30: 158420.44 | J30: Central African Republic | K30: 2477345.5 | Q30: =IFERROR(__xludf.DUMMYFUNCTION("""COMPUTED_VALUE"""),"Tanzania") -> Tanzania | R30: =IFERROR(__xludf.DUMMYFUNCTION("""COMPUTED_VALUE"""),43278.0) -> 43278 | T30: =IFERROR(__xludf.DUMMYFUNCTION("""COMPUTED_VALUE"""),1988.0) -> 1988 | U30: =IFERROR(__xludf.DUMMYFUNCTION("""COMPUTED_VALUE"""),1348014.0) -> 1348014 | V30: =IFERROR(__xludf.DUMMYFUNCTION("""COMPUTED_VALUE"""),1551462.0) -> 1551462 | Y30: Ghana | Z30: {=SUMIFS(cleaned!D30:D7522, cleaned!B30:B7522, dimension!A30:A111, cleaned!C30:C7522, 1976)} -> 5500
B31: =IFERROR(__xludf.DUMMYFUNCTION("""COMPUTED_VALUE"""),1987.0) -> 1987 | C31: =IFERROR(__xludf.DUMMYFUNCTION("""COMPUTED_VALUE"""),1.2833393E7) -> 12833393 | E31: Guadeloupe | F31: 5305.5 | J31: Burundi | K31: 2162310.5 | Q31: =IFERROR(__xludf.DUMMYFUNCTION("""COMPUTED_VALUE"""),"Oceania") -> Oceania | R31: =IFERROR(__xludf.DUMMYFUNCTION("""COMPUTED_VALUE"""),41165.0) -> 41165 | T31: =IFERROR(__xludf.DUMMYFUNCTION("""COMPUTED_VALUE"""),1989.0) -> 1989 | U31: =IFERROR(__xludf.DUMMYFUNCTION("""COMPUTED_VALUE"""),1532335.0) -> 1532335 | V31: =IFERROR(__xludf.DUMMYFUNCTION("""COMPUTED_VALUE"""),1615309.0) -> 1615309 | Y31: Guadeloupe | Z31: {=SUMIFS(cleaned!D31:D7522, cleaned!B31:B7522, dimension!A31:A112, cleaned!C31:C7522, 1976)} -> 116
B32: =IFERROR(__xludf.DUMMYFUNCTION("""COMPUTED_VALUE"""),1988.0) -> 1988 | C32: =IFERROR(__xludf.DUMMYFUNCTION("""COMPUTED_VALUE"""),1.1353206E7) -> 11353206 | E32: Guatemala | F32: 12791943 | J32: Thailand | K32: 2072822.4 | Q32: =IFERROR(__xludf.DUMMYFUNCTION("""COMPUTED_VALUE"""),"Melanesia") -> Melanesia | R32: =IFERROR(__xludf.DUMMYFUNCTION("""COMPUTED_VALUE"""),41041.0) -> 41041 | T32: =IFERROR(__xludf.DUMMYFUNCTION("""COMPUTED_VALUE"""),1990.0) -> 1990 | U32: =IFERROR(__xludf.DUMMYFUNCTION("""COMPUTED_VALUE"""),1464856.0) -> 1464856 | V32: =IFERROR(__xludf.DUMMYFUNCTION("""COMPUTED_VALUE"""),1631852.0) -> 1631852 | Y32: Guatemala | Z32: {=SUMIFS(cleaned!D32:D7522, cleaned!B32:B7522, dimension!A32:A113, cleaned!C32:C7522, 1976)} -> 158433
B33: =IFERROR(__xludf.DUMMYFUNCTION("""COMPUTED_VALUE"""),1989.0) -> 1989 | C33: =IFERROR(__xludf.DUMMYFUNCTION("""COMPUTED_VALUE"""),1.1882162E7) -> 11882162 | E33: Guinea | F33: 3280563.7 | J33: China | K33: 2040412.3 | Q33: =IFERROR(__xludf.DUMMYFUNCTION("""COMPUTED_VALUE"""),"Venezuela") -> Venezuela | R33: =IFERROR(__xludf.DUMMYFUNCTION("""COMPUTED_VALUE"""),40350.0) -> 40350 | T33: =IFERROR(__xludf.DUMMYFUNCTION("""COMPUTED_VALUE"""),1991.0) -> 1991 | U33: =IFERROR(__xludf.DUMMYFUNCTION("""COMPUTED_VALUE"""),1520382.0) -> 1520382 | V33: =IFERROR(__xludf.DUMMYFUNCTION("""COMPUTED_VALUE"""),1650527.0) -> 1650527 | Y33: Guinea | Z33: {=SUMIFS(cleaned!D33:D7522, cleaned!B33:B7522, dimension!A33:A114, cleaned!C33:C7522, 1976)} -> 13975
B34: =IFERROR(__xludf.DUMMYFUNCTION("""COMPUTED_VALUE"""),1990.0) -> 1990 | C34: =IFERROR(__xludf.DUMMYFUNCTION("""COMPUTED_VALUE"""),1.2187206E7) -> 12187206 | E34: Guyana | F34: 38721 | J34: Haiti | K34: 1741216.4 | Q34: =IFERROR(__xludf.DUMMYFUNCTION("""COMPUTED_VALUE"""),"Papua New Guinea") -> Papua New Guinea | R34: =IFERROR(__xludf.DUMMYFUNCTION("""COMPUTED_VALUE"""),39466.0) -> 39466 | T34: =IFERROR(__xludf.DUMMYFUNCTION("""COMPUTED_VALUE"""),1992.0) -> 1992 | U34: =IFERROR(__xludf.DUMMYFUNCTION("""COMPUTED_VALUE"""),1294373.0) -> 1294373 | V34: =IFERROR(__xludf.DUMMYFUNCTION("""COMPUTED_VALUE"""),1671588.0) -> 1671588 | Y34: Guyana | Z34: {=SUMIFS(cleaned!D34:D7522, cleaned!B34:B7522, dimension!A34:A115, cleaned!C34:C7522, 1976)} -> 900
B35: =IFERROR(__xludf.DUMMYFUNCTION("""COMPUTED_VALUE"""),1991.0) -> 1991 | C35: =IFERROR(__xludf.DUMMYFUNCTION("""COMPUTED_VALUE"""),1.2173584990000002E7) -> 12173585 | E35: Haiti | F35: 1741216.4 | J35: Rwanda | K35: 1358374 | Q35: =IFERROR(__xludf.DUMMYFUNCTION("""COMPUTED_VALUE"""),"Haiti") -> Haiti | R35: =IFERROR(__xludf.DUMMYFUNCTION("""COMPUTED_VALUE"""),32280.0) -> 32280 | T35: =IFERROR(__xludf.DUMMYFUNCTION("""COMPUTED_VALUE"""),1993.0) -> 1993 | U35: =IFERROR(__xludf.DUMMYFUNCTION("""COMPUTED_VALUE"""),1278759.0) -> 1278759 | V35: =IFERROR(__xludf.DUMMYFUNCTION("""COMPUTED_VALUE"""),1689366.0) -> 1689366 | Y35: Haiti | Z35: {=SUMIFS(cleaned!D35:D7522, cleaned!B35:B7522, dimension!A35:A116, cleaned!C35:C7522, 1976)} -> 32280
B36: =IFERROR(__xludf.DUMMYFUNCTION("""COMPUTED_VALUE"""),1992.0) -> 1992 | C36: =IFERROR(__xludf.DUMMYFUNCTION("""COMPUTED_VALUE"""),1.222352304E7) -> 12223523 | E36: Honduras | F36: 10332337 | J36: Bolivia | K36: 1246437.3 | Q36: =IFERROR(__xludf.DUMMYFUNCTION("""COMPUTED_VALUE"""),"Cuba") -> Cuba | R36: =IFERROR(__xludf.DUMMYFUNCTION("""COMPUTED_VALUE"""),27151.0) -> 27151 | T36: =IFERROR(__xludf.DUMMYFUNCTION("""COMPUTED_VALUE"""),1994.0) -> 1994 | U36: =IFERROR(__xludf.DUMMYFUNCTION("""COMPUTED_VALUE"""),1307289.0) -> 1307289 | V36: =IFERROR(__xludf.DUMMYFUNCTION("""COMPUTED_VALUE"""),1819569.0) -> 1819569 | Y36: Honduras | Z36: {=SUMIFS(cleaned!D36:D7522, cleaned!B36:B7522, dimension!A36:A117, cleaned!C36:C7522, 1976)} -> 48285
B37: =IFERROR(__xludf.DUMMYFUNCTION("""COMPUTED_VALUE"""),1993.0) -> 1993 | C37: =IFERROR(__xludf.DUMMYFUNCTION("""COMPUTED_VALUE"""),1.117373872E7) -> 11173739 | E37: India | F37: 12584852 | J37: Cuba | K37: 1202993.3 | Q37: =IFERROR(__xludf.DUMMYFUNCTION("""COMPUTED_VALUE"""),"Burundi") -> Burundi | R37: =IFERROR(__xludf.DUMMYFUNCTION("""COMPUTED_VALUE"""),21428.0) -> 21428 | T37: =IFERROR(__xludf.DUMMYFUNCTION("""COMPUTED_VALUE"""),1995.0) -> 1995 | U37: =IFERROR(__xludf.DUMMYFUNCTION("""COMPUTED_VALUE"""),930135.0) -> 930135 | V37: =IFERROR(__xludf.DUMMYFUNCTION("""COMPUTED_VALUE"""),1903562.0) -> 1903562 | Y37: India | Z37: {=SUMIFS(cleaned!D37:D7522, cleaned!B37:B7522, dimension!A37:A118, cleaned!C37:C7522, 1976)} -> 84000
B38: =IFERROR(__xludf.DUMMYFUNCTION("""COMPUTED_VALUE"""),1994.0) -> 1994 | C38: =IFERROR(__xludf.DUMMYFUNCTION("""COMPUTED_VALUE"""),1.151270246E7) -> 11512702 | E38: Indonesia | F38: 28224094 | J38: Sierra Leone | K38: 905539.8 | Q38: =IFERROR(__xludf.DUMMYFUNCTION("""COMPUTED_VALUE"""),"Rwanda") -> Rwanda | R38: =IFERROR(__xludf.DUMMYFUNCTION("""COMPUTED_VALUE"""),20334.0) -> 20334 | T38: =IFERROR(__xludf.DUMMYFUNCTION("""COMPUTED_VALUE"""),1996.0) -> 1996 | U38: =IFERROR(__xludf.DUMMYFUNCTION("""COMPUTED_VALUE"""),1369196.0) -> 1369196 | V38: =IFERROR(__xludf.DUMMYFUNCTION("""COMPUTED_VALUE"""),1910646.0) -> 1910646 | Y38: Indonesia | Z38: {=SUMIFS(cleaned!D38:D7522, cleaned!B38:B7522, dimension!A38:A119, cleaned!C38:C7522, 1976)} -> 193377
B39: =IFERROR(__xludf.DUMMYFUNCTION("""COMPUTED_VALUE"""),1995.0) -> 1995 | C39: =IFERROR(__xludf.DUMMYFUNCTION("""COMPUTED_VALUE"""),1.111802398E7) -> 11118024 | E39: Jamaica | F39: 245584.9 | J39: Togo | K39: 807800.86 | Q39: =IFERROR(__xludf.DUMMYFUNCTION("""COMPUTED_VALUE"""),"Bolivia") -> Bolivia | R39: =IFERROR(__xludf.DUMMYFUNCTION("""COMPUTED_VALUE"""),14664.0) -> 14664 | T39: =IFERROR(__xludf.DUMMYFUNCTION("""COMPUTED_VALUE"""),1997.0) -> 1997 | U39: =IFERROR(__xludf.DUMMYFUNCTION("""COMPUTED_VALUE"""),1228513.0) -> 1228513 | V39: =IFERROR(__xludf.DUMMYFUNCTION("""COMPUTED_VALUE"""),1987074.0) -> 1987074 | Y39: Jamaica | Z39: {=SUMIFS(cleaned!D39:D7522, cleaned!B39:B7522, dimension!A39:A120, cleaned!C39:C7522, 1976)} -> 1929
B40: =IFERROR(__xludf.DUMMYFUNCTION("""COMPUTED_VALUE"""),1996.0) -> 1996 | C40: =IFERROR(__xludf.DUMMYFUNCTION("""COMPUTED_VALUE"""),1.24606069E7) -> 12460607 | E40: Kenya | F40: 4181454 | J40: Yemen | K40: 709152.68 | Q40: =IFERROR(__xludf.DUMMYFUNCTION("""COMPUTED_VALUE"""),"Guinea") -> Guinea | R40: =IFERROR(__xludf.DUMMYFUNCTION("""COMPUTED_VALUE"""),13975.0) -> 13975 | T40: =IFERROR(__xludf.DUMMYFUNCTION("""COMPUTED_VALUE"""),1998.0) -> 1998 | U40: =IFERROR(__xludf.DUMMYFUNCTION("""COMPUTED_VALUE"""),1689366.0) -> 1689366 | V40: =IFERROR(__xludf.DUMMYFUNCTION("""COMPUTED_VALUE"""),2032210.0) -> 2032210 | Y40: Kenya | Z40: {=SUMIFS(cleaned!D40:D7522, cleaned!B40:B7522, dimension!A40:A121, cleaned!C40:C7522, 1976)} -> 80303
...
